root - INFO - Bot started...
apscheduler.scheduler - INFO - Scheduler started
2021-09-13 15:37:54,433 - root - INFO - Bot started...
2021-09-13 15:37:54,433 - apscheduler.scheduler - INFO - Scheduler started
2021-09-13 16:06:07,049 - root - INFO - Bot started...
2021-09-13 16:06:07,054 - apscheduler.scheduler - INFO - Scheduler started
2021-09-13 16:08:14,129 - root - INFO - Bot started...
2021-09-13 16:08:14,133 - apscheduler.scheduler - INFO - Scheduler started
2021-09-13 16:09:26,072 - root - INFO - Bot started...
2021-09-13 16:09:26,079 - apscheduler.scheduler - INFO - Scheduler started
2021-09-13 16:09:29,133 - root - INFO - jgjhgj
2021-09-13 16:41:57,964 - root - INFO - –ü—Ä–∏–≤–µ—Ç –±–æ—Ç!

–ö–∞–∫ –¥–µ–ª–∞?
2021-09-13 16:44:45,203 - root - INFO - –ø—Ä–∏–≤–µ—Ç
2021-09-13 16:52:10,263 - root - INFO - Bot started...
2021-09-13 16:52:10,267 - apscheduler.scheduler - INFO - Scheduler started
2021-09-13 16:52:10,963 - telegram.ext.dispatcher - ERROR - No error handlers are registered, logging exception.
Traceback (most recent call last):
  File "C:\Users\user\AppData\Local\Programs\Python\Python39\lib\site-packages\telegram\ext\dispatcher.py", line 555, in process_update
    handler.handle_update(update, self, check, context)
  File "C:\Users\user\AppData\Local\Programs\Python\Python39\lib\site-packages\telegram\ext\handler.py", line 198, in handle_update
    return self.callback(update, context)
  File "d:\Python\learn1\simplebot\bot.py", line 26, in chat
    logging.info(mytext.decode('utf-8'))
AttributeError: 'str' object has no attribute 'decode'
2021-09-13 16:52:10,963 - telegram.ext.dispatcher - ERROR - No error handlers are registered, logging exception.
Traceback (most recent call last):
  File "C:\Users\user\AppData\Local\Programs\Python\Python39\lib\site-packages\telegram\ext\dispatcher.py", line 555, in process_update
    handler.handle_update(update, self, check, context)
  File "C:\Users\user\AppData\Local\Programs\Python\Python39\lib\site-packages\telegram\ext\handler.py", line 198, in handle_update
    return self.callback(update, context)
  File "d:\Python\learn1\simplebot\bot.py", line 26, in chat
    logging.info(mytext.decode('utf-8'))
AttributeError: 'str' object has no attribute 'decode'
2021-09-13 16:52:10,963 - telegram.ext.dispatcher - ERROR - No error handlers are registered, logging exception.
Traceback (most recent call last):
  File "C:\Users\user\AppData\Local\Programs\Python\Python39\lib\site-packages\telegram\ext\dispatcher.py", line 555, in process_update
    handler.handle_update(update, self, check, context)
  File "C:\Users\user\AppData\Local\Programs\Python\Python39\lib\site-packages\telegram\ext\handler.py", line 198, in handle_update
    return self.callback(update, context)
  File "d:\Python\learn1\simplebot\bot.py", line 26, in chat
    logging.info(mytext.decode('utf-8'))
AttributeError: 'str' object has no attribute 'decode'
2021-09-13 16:52:11,605 - telegram.ext.dispatcher - ERROR - No error handlers are registered, logging exception.
Traceback (most recent call last):
  File "C:\Users\user\AppData\Local\Programs\Python\Python39\lib\site-packages\telegram\ext\dispatcher.py", line 555, in process_update
    handler.handle_update(update, self, check, context)
  File "C:\Users\user\AppData\Local\Programs\Python\Python39\lib\site-packages\telegram\ext\handler.py", line 198, in handle_update
    return self.callback(update, context)
  File "d:\Python\learn1\simplebot\bot.py", line 26, in chat
    logging.info(mytext.decode('utf-8'))
AttributeError: 'str' object has no attribute 'decode'
2021-09-13 16:52:20,069 - telegram.ext.dispatcher - ERROR - No error handlers are registered, logging exception.
Traceback (most recent call last):
  File "C:\Users\user\AppData\Local\Programs\Python\Python39\lib\site-packages\telegram\ext\dispatcher.py", line 555, in process_update
    handler.handle_update(update, self, check, context)
  File "C:\Users\user\AppData\Local\Programs\Python\Python39\lib\site-packages\telegram\ext\handler.py", line 198, in handle_update
    return self.callback(update, context)
  File "d:\Python\learn1\simplebot\bot.py", line 26, in chat
    logging.info(mytext.decode('utf-8'))
AttributeError: 'str' object has no attribute 'decode'
2021-09-13 16:56:05,673 - root - INFO - Bot started...
2021-09-13 16:56:05,673 - apscheduler.scheduler - INFO - Scheduler started
2021-09-13 16:56:17,771 - root - INFO - b'\xd0\xbf\xd1\x80\xd0\xb8\xd0\xb2\xd0\xb5\xd1\x82'
2021-09-13 16:59:05,258 - root - INFO - b'\xd0\xbf\xd1\x80\xd0\xb8\xd0\xb2\xd0\xb5\xd1\x82!\n\n\xd0\xba\xd0\xb0\xd0\xba \xd0\xb4\xd0\xb5\xd0\xbb\xd0\xb0?'
2021-09-13 17:13:31,623 - root - INFO - Bot started...
2021-09-13 17:13:31,627 - apscheduler.scheduler - INFO - Scheduler started
2021-09-13 17:13:45,520 - telegram.ext.dispatcher - ERROR - No error handlers are registered, logging exception.
Traceback (most recent call last):
  File "C:\Users\user\AppData\Local\Programs\Python\Python39\lib\site-packages\telegram\ext\dispatcher.py", line 555, in process_update
    handler.handle_update(update, self, check, context)
  File "C:\Users\user\AppData\Local\Programs\Python\Python39\lib\site-packages\telegram\ext\handler.py", line 198, in handle_update
    return self.callback(update, context)
  File "d:\Python\learn1\simplebot\bot.py", line 26, in chat
    logging.info(mytext.encode('ascii'))
UnicodeEncodeError: 'ascii' codec can't encode characters in position 0-5: ordinal not in range(128)
2021-09-13 17:22:35,238 - root - INFO - Bot started...
2021-09-13 17:22:35,243 - apscheduler.scheduler - INFO - Scheduler started
2021-09-13 17:22:40,751 - root - INFO - b'\xd0\xbf\xd1\x80\xd0\xb8\xd0\xb2\xd0\xb5\xd1\x82'
2021-09-13 17:23:03,204 - root - INFO - Bot started...
2021-09-13 17:23:03,206 - apscheduler.scheduler - INFO - Scheduler started
2021-09-13 17:23:06,970 - root - INFO - ??????
2021-09-13 17:26:19,237 - root - INFO - Bot started...
2021-09-13 17:26:19,242 - apscheduler.scheduler - INFO - Scheduler started
2021-09-13 17:26:42,509 - root - INFO - ??????
2021-09-13 17:33:47,013 - root - INFO - Bot started...
2021-09-13 17:33:47,018 - apscheduler.scheduler - INFO - Scheduler started
2021-09-13 17:33:51,939 - root - INFO - ÔË‚ÂÚ
2021-09-13 17:49:53,099 - root - INFO - Bot started...
2021-09-13 17:49:53,103 - apscheduler.scheduler - INFO - Scheduler started
2021-09-13 17:51:18,322 - root - INFO - Bot started...
2021-09-13 17:51:18,327 - apscheduler.scheduler - INFO - Scheduler started
2021-09-13 18:07:01,949 - root - INFO - Bot started...
2021-09-13 18:07:01,953 - apscheduler.scheduler - INFO - Scheduler started
2021-09-13 18:07:14,377 - root - INFO - b'\xd0\xbf\xd1\x80\xd0\xb8\xd0\xb2\xd0\xb5\xd1\x82'
2021-09-13 18:08:14,369 - root - INFO - Bot started...
2021-09-13 18:08:14,373 - apscheduler.scheduler - INFO - Scheduler started
2021-09-13 18:08:21,727 - root - INFO - ÔË‚ÂÚ
2021-09-13 18:09:37,570 - root - INFO - Bot started...
2021-09-13 18:09:37,570 - apscheduler.scheduler - INFO - Scheduler started
2021-09-13 18:09:41,913 - root - INFO - ÔË‚ÂÚ
2021-09-13 18:12:44,194 - telegram.ext.updater - ERROR - Error while getting Updates: urllib3 HTTPError ('Connection aborted.', RemoteDisconnected('Remote end closed connection without response'))
2021-09-13 18:12:44,194 - telegram.ext.dispatcher - ERROR - No error handlers are registered, logging exception.
Traceback (most recent call last):
  File "C:\Users\user\AppData\Local\Programs\Python\Python39\lib\site-packages\telegram\vendor\ptb_urllib3\urllib3\connectionpool.py", line 614, in urlopen
    httplib_response = self._make_request(conn, method, url,
  File "C:\Users\user\AppData\Local\Programs\Python\Python39\lib\site-packages\telegram\vendor\ptb_urllib3\urllib3\connectionpool.py", line 402, in _make_request
    six.raise_from(e, None)
  File "<string>", line 2, in raise_from
  File "C:\Users\user\AppData\Local\Programs\Python\Python39\lib\site-packages\telegram\vendor\ptb_urllib3\urllib3\connectionpool.py", line 398, in _make_request
    httplib_response = conn.getresponse()
  File "C:\Users\user\AppData\Local\Programs\Python\Python39\lib\http\client.py", line 1371, in getresponse
    response.begin()
  File "C:\Users\user\AppData\Local\Programs\Python\Python39\lib\http\client.py", line 319, in begin
    version, status, reason = self._read_status()
  File "C:\Users\user\AppData\Local\Programs\Python\Python39\lib\http\client.py", line 288, in _read_status
    raise RemoteDisconnected("Remote end closed connection without"
http.client.RemoteDisconnected: Remote end closed connection without response

During handling of the above exception, another exception occurred:

Traceback (most recent call last):
  File "C:\Users\user\AppData\Local\Programs\Python\Python39\lib\site-packages\telegram\utils\request.py", line 259, in _request_wrapper
    resp = self._con_pool.request(*args, **kwargs)
  File "C:\Users\user\AppData\Local\Programs\Python\Python39\lib\site-packages\telegram\vendor\ptb_urllib3\urllib3\request.py", line 68, in request
    return self.request_encode_body(method, url, fields=fields,
  File "C:\Users\user\AppData\Local\Programs\Python\Python39\lib\site-packages\telegram\vendor\ptb_urllib3\urllib3\request.py", line 148, in request_encode_body
    return self.urlopen(method, url, **extra_kw)
  File "C:\Users\user\AppData\Local\Programs\Python\Python39\lib\site-packages\telegram\vendor\ptb_urllib3\urllib3\poolmanager.py", line 244, in urlopen
    response = conn.urlopen(method, u.request_uri, **kw)
  File "C:\Users\user\AppData\Local\Programs\Python\Python39\lib\site-packages\telegram\vendor\ptb_urllib3\urllib3\connectionpool.py", line 665, in urlopen
    retries = retries.increment(method, url, error=e, _pool=self,
  File "C:\Users\user\AppData\Local\Programs\Python\Python39\lib\site-packages\telegram\vendor\ptb_urllib3\urllib3\util\retry.py", line 347, in increment
    raise six.reraise(type(error), error, _stacktrace)
  File "C:\Users\user\AppData\Local\Programs\Python\Python39\lib\site-packages\telegram\vendor\ptb_urllib3\urllib3\packages\six.py", line 685, in reraise
    raise value.with_traceback(tb)
  File "C:\Users\user\AppData\Local\Programs\Python\Python39\lib\site-packages\telegram\vendor\ptb_urllib3\urllib3\connectionpool.py", line 614, in urlopen
    httplib_response = self._make_request(conn, method, url,
  File "C:\Users\user\AppData\Local\Programs\Python\Python39\lib\site-packages\telegram\vendor\ptb_urllib3\urllib3\connectionpool.py", line 402, in _make_request
    six.raise_from(e, None)
  File "<string>", line 2, in raise_from
  File "C:\Users\user\AppData\Local\Programs\Python\Python39\lib\site-packages\telegram\vendor\ptb_urllib3\urllib3\connectionpool.py", line 398, in _make_request
    httplib_response = conn.getresponse()
  File "C:\Users\user\AppData\Local\Programs\Python\Python39\lib\http\client.py", line 1371, in getresponse
    response.begin()
  File "C:\Users\user\AppData\Local\Programs\Python\Python39\lib\http\client.py", line 319, in begin
    version, status, reason = self._read_status()
  File "C:\Users\user\AppData\Local\Programs\Python\Python39\lib\http\client.py", line 288, in _read_status
    raise RemoteDisconnected("Remote end closed connection without"
telegram.vendor.ptb_urllib3.urllib3.exceptions.ProtocolError: ('Connection aborted.', RemoteDisconnected('Remote end closed connection without response'))

The above exception was the direct cause of the following exception:

Traceback (most recent call last):
  File "C:\Users\user\AppData\Local\Programs\Python\Python39\lib\site-packages\telegram\ext\updater.py", line 646, in _network_loop_retry
    if not action_cb():
  File "C:\Users\user\AppData\Local\Programs\Python\Python39\lib\site-packages\telegram\ext\updater.py", line 597, in polling_action_cb
    updates = self.bot.get_updates(
  File "C:\Users\user\AppData\Local\Programs\Python\Python39\lib\site-packages\telegram\ext\extbot.py", line 222, in get_updates
    updates = super().get_updates(
  File "C:\Users\user\AppData\Local\Programs\Python\Python39\lib\site-packages\telegram\bot.py", line 130, in decorator
    result = func(*args, **kwargs)
  File "C:\Users\user\AppData\Local\Programs\Python\Python39\lib\site-packages\telegram\bot.py", line 2861, in get_updates
    self._post(
  File "C:\Users\user\AppData\Local\Programs\Python\Python39\lib\site-packages\telegram\bot.py", line 295, in _post
    return self.request.post(
  File "C:\Users\user\AppData\Local\Programs\Python\Python39\lib\site-packages\telegram\utils\request.py", line 356, in post
    result = self._request_wrapper(
  File "C:\Users\user\AppData\Local\Programs\Python\Python39\lib\site-packages\telegram\utils\request.py", line 265, in _request_wrapper
    raise NetworkError(f'urllib3 HTTPError {error}') from error
telegram.error.NetworkError: urllib3 HTTPError ('Connection aborted.', RemoteDisconnected('Remote end closed connection without response'))
2021-09-14 10:04:09,449 - root - INFO - Bot started...
2021-09-14 10:04:09,468 - apscheduler.scheduler - INFO - Scheduler started
2021-09-14 10:06:35,090 - root - INFO - ÔË‚ÂÚ
2021-09-14 14:01:15,729 - root - INFO - Bot started...
2021-09-14 14:01:15,729 - apscheduler.scheduler - INFO - Scheduler started
2021-09-14 14:01:16,261 - telegram.ext.updater - ERROR - Error while getting Updates: Conflict: terminated by other getUpdates request; make sure that only one bot instance is running
2021-09-14 14:01:16,261 - telegram.ext.dispatcher - ERROR - No error handlers are registered, logging exception.
Traceback (most recent call last):
  File "C:\Users\user\AppData\Local\Programs\Python\Python39\lib\site-packages\telegram\ext\updater.py", line 646, in _network_loop_retry
    if not action_cb():
  File "C:\Users\user\AppData\Local\Programs\Python\Python39\lib\site-packages\telegram\ext\updater.py", line 597, in polling_action_cb
    updates = self.bot.get_updates(
  File "C:\Users\user\AppData\Local\Programs\Python\Python39\lib\site-packages\telegram\ext\extbot.py", line 222, in get_updates
    updates = super().get_updates(
  File "C:\Users\user\AppData\Local\Programs\Python\Python39\lib\site-packages\telegram\bot.py", line 130, in decorator
    result = func(*args, **kwargs)
  File "C:\Users\user\AppData\Local\Programs\Python\Python39\lib\site-packages\telegram\bot.py", line 2861, in get_updates
    self._post(
  File "C:\Users\user\AppData\Local\Programs\Python\Python39\lib\site-packages\telegram\bot.py", line 295, in _post
    return self.request.post(
  File "C:\Users\user\AppData\Local\Programs\Python\Python39\lib\site-packages\telegram\utils\request.py", line 356, in post
    result = self._request_wrapper(
  File "C:\Users\user\AppData\Local\Programs\Python\Python39\lib\site-packages\telegram\utils\request.py", line 283, in _request_wrapper
    raise Conflict(message)
telegram.error.Conflict: Conflict: terminated by other getUpdates request; make sure that only one bot instance is running
2021-09-14 14:01:20,373 - telegram.ext.updater - ERROR - Error while getting Updates: Conflict: terminated by other getUpdates request; make sure that only one bot instance is running
2021-09-14 14:01:20,374 - telegram.ext.dispatcher - ERROR - No error handlers are registered, logging exception.
Traceback (most recent call last):
  File "C:\Users\user\AppData\Local\Programs\Python\Python39\lib\site-packages\telegram\ext\updater.py", line 646, in _network_loop_retry
    if not action_cb():
  File "C:\Users\user\AppData\Local\Programs\Python\Python39\lib\site-packages\telegram\ext\updater.py", line 597, in polling_action_cb
    updates = self.bot.get_updates(
  File "C:\Users\user\AppData\Local\Programs\Python\Python39\lib\site-packages\telegram\ext\extbot.py", line 222, in get_updates
    updates = super().get_updates(
  File "C:\Users\user\AppData\Local\Programs\Python\Python39\lib\site-packages\telegram\bot.py", line 130, in decorator
    result = func(*args, **kwargs)
  File "C:\Users\user\AppData\Local\Programs\Python\Python39\lib\site-packages\telegram\bot.py", line 2861, in get_updates
    self._post(
  File "C:\Users\user\AppData\Local\Programs\Python\Python39\lib\site-packages\telegram\bot.py", line 295, in _post
    return self.request.post(
  File "C:\Users\user\AppData\Local\Programs\Python\Python39\lib\site-packages\telegram\utils\request.py", line 356, in post
    result = self._request_wrapper(
  File "C:\Users\user\AppData\Local\Programs\Python\Python39\lib\site-packages\telegram\utils\request.py", line 283, in _request_wrapper
    raise Conflict(message)
telegram.error.Conflict: Conflict: terminated by other getUpdates request; make sure that only one bot instance is running
2021-09-14 14:01:21,475 - telegram.ext.updater - ERROR - Error while getting Updates: Conflict: terminated by other getUpdates request; make sure that only one bot instance is running
2021-09-14 14:01:21,475 - telegram.ext.dispatcher - ERROR - No error handlers are registered, logging exception.
Traceback (most recent call last):
  File "C:\Users\user\AppData\Local\Programs\Python\Python39\lib\site-packages\telegram\ext\updater.py", line 646, in _network_loop_retry
    if not action_cb():
  File "C:\Users\user\AppData\Local\Programs\Python\Python39\lib\site-packages\telegram\ext\updater.py", line 597, in polling_action_cb
    updates = self.bot.get_updates(
  File "C:\Users\user\AppData\Local\Programs\Python\Python39\lib\site-packages\telegram\ext\extbot.py", line 222, in get_updates
    updates = super().get_updates(
  File "C:\Users\user\AppData\Local\Programs\Python\Python39\lib\site-packages\telegram\bot.py", line 130, in decorator
    result = func(*args, **kwargs)
  File "C:\Users\user\AppData\Local\Programs\Python\Python39\lib\site-packages\telegram\bot.py", line 2861, in get_updates
    self._post(
  File "C:\Users\user\AppData\Local\Programs\Python\Python39\lib\site-packages\telegram\bot.py", line 295, in _post
    return self.request.post(
  File "C:\Users\user\AppData\Local\Programs\Python\Python39\lib\site-packages\telegram\utils\request.py", line 356, in post
    result = self._request_wrapper(
  File "C:\Users\user\AppData\Local\Programs\Python\Python39\lib\site-packages\telegram\utils\request.py", line 283, in _request_wrapper
    raise Conflict(message)
telegram.error.Conflict: Conflict: terminated by other getUpdates request; make sure that only one bot instance is running
2021-09-14 14:01:24,158 - root - INFO - Bot started...
2021-09-14 14:01:24,159 - apscheduler.scheduler - INFO - Scheduler started
2021-09-14 14:01:49,868 - root - INFO - ÔË‚ÂÚ
2021-09-14 14:02:13,448 - root - INFO - hhello
2021-09-14 14:06:21,645 - root - INFO - Bot started...
2021-09-14 14:06:21,646 - apscheduler.scheduler - INFO - Scheduler started
2021-09-14 14:06:34,070 - telegram.vendor.ptb_urllib3.urllib3.connectionpool - WARNING - Retrying (Retry(total=2, connect=None, read=None, redirect=None)) after connection broken by 'NewConnectionError('<telegram.vendor.ptb_urllib3.urllib3.connection.VerifiedHTTPSConnection object at 0x0000026A98FBEB80>: Failed to establish a new connection: [Errno 11001] getaddrinfo failed')': /bot1962228157:AAFEnQahitcgf3WyttR3ZpdUiBLWLQtU0WY/getUpdates
2021-09-14 14:06:34,085 - telegram.vendor.ptb_urllib3.urllib3.connectionpool - WARNING - Retrying (Retry(total=1, connect=None, read=None, redirect=None)) after connection broken by 'NewConnectionError('<telegram.vendor.ptb_urllib3.urllib3.connection.VerifiedHTTPSConnection object at 0x0000026A98FA8EE0>: Failed to establish a new connection: [Errno 11001] getaddrinfo failed')': /bot1962228157:AAFEnQahitcgf3WyttR3ZpdUiBLWLQtU0WY/getUpdates
2021-09-14 14:06:34,086 - telegram.vendor.ptb_urllib3.urllib3.connectionpool - WARNING - Retrying (Retry(total=0, connect=None, read=None, redirect=None)) after connection broken by 'NewConnectionError('<telegram.vendor.ptb_urllib3.urllib3.connection.VerifiedHTTPSConnection object at 0x0000026A98FBEAC0>: Failed to establish a new connection: [Errno 11001] getaddrinfo failed')': /bot1962228157:AAFEnQahitcgf3WyttR3ZpdUiBLWLQtU0WY/getUpdates
2021-09-14 14:06:34,086 - telegram.ext.updater - ERROR - Error while getting Updates: urllib3 HTTPError HTTPSConnectionPool(host='api.telegram.org', port=443): Max retries exceeded with url: /bot1962228157:AAFEnQahitcgf3WyttR3ZpdUiBLWLQtU0WY/getUpdates (Caused by NewConnectionError('<telegram.vendor.ptb_urllib3.urllib3.connection.VerifiedHTTPSConnection object at 0x0000026A98FCF2E0>: Failed to establish a new connection: [Errno 11001] getaddrinfo failed'))
2021-09-14 14:06:34,086 - telegram.ext.dispatcher - ERROR - No error handlers are registered, logging exception.
Traceback (most recent call last):
  File "C:\Users\user\AppData\Local\Programs\Python\Python39\lib\site-packages\telegram\vendor\ptb_urllib3\urllib3\connection.py", line 140, in _new_conn
    conn = connection.create_connection(
  File "C:\Users\user\AppData\Local\Programs\Python\Python39\lib\site-packages\telegram\vendor\ptb_urllib3\urllib3\util\connection.py", line 60, in create_connection
    for res in socket.getaddrinfo(host, port, family, socket.SOCK_STREAM):
  File "C:\Users\user\AppData\Local\Programs\Python\Python39\lib\socket.py", line 954, in getaddrinfo
    for res in _socket.getaddrinfo(host, port, family, type, proto, flags):
socket.gaierror: [Errno 11001] getaddrinfo failed

During handling of the above exception, another exception occurred:

Traceback (most recent call last):
  File "C:\Users\user\AppData\Local\Programs\Python\Python39\lib\site-packages\telegram\vendor\ptb_urllib3\urllib3\connectionpool.py", line 614, in urlopen
    httplib_response = self._make_request(conn, method, url,
  File "C:\Users\user\AppData\Local\Programs\Python\Python39\lib\site-packages\telegram\vendor\ptb_urllib3\urllib3\connectionpool.py", line 360, in _make_request
    self._validate_conn(conn)
  File "C:\Users\user\AppData\Local\Programs\Python\Python39\lib\site-packages\telegram\vendor\ptb_urllib3\urllib3\connectionpool.py", line 857, in _validate_conn
    super(HTTPSConnectionPool, self)._validate_conn(conn)
  File "C:\Users\user\AppData\Local\Programs\Python\Python39\lib\site-packages\telegram\vendor\ptb_urllib3\urllib3\connectionpool.py", line 289, in _validate_conn
    conn.connect()
  File "C:\Users\user\AppData\Local\Programs\Python\Python39\lib\site-packages\telegram\vendor\ptb_urllib3\urllib3\connection.py", line 284, in connect
    conn = self._new_conn()
  File "C:\Users\user\AppData\Local\Programs\Python\Python39\lib\site-packages\telegram\vendor\ptb_urllib3\urllib3\connection.py", line 149, in _new_conn
    raise NewConnectionError(
telegram.vendor.ptb_urllib3.urllib3.exceptions.NewConnectionError: <telegram.vendor.ptb_urllib3.urllib3.connection.VerifiedHTTPSConnection object at 0x0000026A98FCF2E0>: Failed to establish a new connection: [Errno 11001] getaddrinfo failed

During handling of the above exception, another exception occurred:

Traceback (most recent call last):
  File "C:\Users\user\AppData\Local\Programs\Python\Python39\lib\site-packages\telegram\utils\request.py", line 259, in _request_wrapper
    resp = self._con_pool.request(*args, **kwargs)
  File "C:\Users\user\AppData\Local\Programs\Python\Python39\lib\site-packages\telegram\vendor\ptb_urllib3\urllib3\request.py", line 68, in request
    return self.request_encode_body(method, url, fields=fields,
  File "C:\Users\user\AppData\Local\Programs\Python\Python39\lib\site-packages\telegram\vendor\ptb_urllib3\urllib3\request.py", line 148, in request_encode_body
    return self.urlopen(method, url, **extra_kw)
  File "C:\Users\user\AppData\Local\Programs\Python\Python39\lib\site-packages\telegram\vendor\ptb_urllib3\urllib3\poolmanager.py", line 244, in urlopen
    response = conn.urlopen(method, u.request_uri, **kw)
  File "C:\Users\user\AppData\Local\Programs\Python\Python39\lib\site-packages\telegram\vendor\ptb_urllib3\urllib3\connectionpool.py", line 691, in urlopen
    return self.urlopen(method, url, body, headers, retries,
  File "C:\Users\user\AppData\Local\Programs\Python\Python39\lib\site-packages\telegram\vendor\ptb_urllib3\urllib3\connectionpool.py", line 691, in urlopen
    return self.urlopen(method, url, body, headers, retries,
  File "C:\Users\user\AppData\Local\Programs\Python\Python39\lib\site-packages\telegram\vendor\ptb_urllib3\urllib3\connectionpool.py", line 691, in urlopen
    return self.urlopen(method, url, body, headers, retries,
  File "C:\Users\user\AppData\Local\Programs\Python\Python39\lib\site-packages\telegram\vendor\ptb_urllib3\urllib3\connectionpool.py", line 665, in urlopen
    retries = retries.increment(method, url, error=e, _pool=self,
  File "C:\Users\user\AppData\Local\Programs\Python\Python39\lib\site-packages\telegram\vendor\ptb_urllib3\urllib3\util\retry.py", line 376, in increment
    raise MaxRetryError(_pool, url, error or ResponseError(cause))
telegram.vendor.ptb_urllib3.urllib3.exceptions.MaxRetryError: HTTPSConnectionPool(host='api.telegram.org', port=443): Max retries exceeded with url: /bot1962228157:AAFEnQahitcgf3WyttR3ZpdUiBLWLQtU0WY/getUpdates (Caused by NewConnectionError('<telegram.vendor.ptb_urllib3.urllib3.connection.VerifiedHTTPSConnection object at 0x0000026A98FCF2E0>: Failed to establish a new connection: [Errno 11001] getaddrinfo failed'))

The above exception was the direct cause of the following exception:

Traceback (most recent call last):
  File "C:\Users\user\AppData\Local\Programs\Python\Python39\lib\site-packages\telegram\ext\updater.py", line 646, in _network_loop_retry
    if not action_cb():
  File "C:\Users\user\AppData\Local\Programs\Python\Python39\lib\site-packages\telegram\ext\updater.py", line 597, in polling_action_cb
    updates = self.bot.get_updates(
  File "C:\Users\user\AppData\Local\Programs\Python\Python39\lib\site-packages\telegram\ext\extbot.py", line 222, in get_updates
    updates = super().get_updates(
  File "C:\Users\user\AppData\Local\Programs\Python\Python39\lib\site-packages\telegram\bot.py", line 130, in decorator
    result = func(*args, **kwargs)
  File "C:\Users\user\AppData\Local\Programs\Python\Python39\lib\site-packages\telegram\bot.py", line 2861, in get_updates
    self._post(
  File "C:\Users\user\AppData\Local\Programs\Python\Python39\lib\site-packages\telegram\bot.py", line 295, in _post
    return self.request.post(
  File "C:\Users\user\AppData\Local\Programs\Python\Python39\lib\site-packages\telegram\utils\request.py", line 356, in post
    result = self._request_wrapper(
  File "C:\Users\user\AppData\Local\Programs\Python\Python39\lib\site-packages\telegram\utils\request.py", line 265, in _request_wrapper
    raise NetworkError(f'urllib3 HTTPError {error}') from error
telegram.error.NetworkError: urllib3 HTTPError HTTPSConnectionPool(host='api.telegram.org', port=443): Max retries exceeded with url: /bot1962228157:AAFEnQahitcgf3WyttR3ZpdUiBLWLQtU0WY/getUpdates (Caused by NewConnectionError('<telegram.vendor.ptb_urllib3.urllib3.connection.VerifiedHTTPSConnection object at 0x0000026A98FCF2E0>: Failed to establish a new connection: [Errno 11001] getaddrinfo failed'))
2021-09-14 14:06:35,087 - telegram.vendor.ptb_urllib3.urllib3.connectionpool - WARNING - Retrying (Retry(total=2, connect=None, read=None, redirect=None)) after connection broken by 'NewConnectionError('<telegram.vendor.ptb_urllib3.urllib3.connection.VerifiedHTTPSConnection object at 0x0000026A98FCF460>: Failed to establish a new connection: [Errno 11001] getaddrinfo failed')': /bot1962228157:AAFEnQahitcgf3WyttR3ZpdUiBLWLQtU0WY/getUpdates
2021-09-14 14:06:35,088 - telegram.vendor.ptb_urllib3.urllib3.connectionpool - WARNING - Retrying (Retry(total=1, connect=None, read=None, redirect=None)) after connection broken by 'NewConnectionError('<telegram.vendor.ptb_urllib3.urllib3.connection.VerifiedHTTPSConnection object at 0x0000026A98FCF820>: Failed to establish a new connection: [Errno 11001] getaddrinfo failed')': /bot1962228157:AAFEnQahitcgf3WyttR3ZpdUiBLWLQtU0WY/getUpdates
2021-09-14 14:06:35,088 - telegram.vendor.ptb_urllib3.urllib3.connectionpool - WARNING - Retrying (Retry(total=0, connect=None, read=None, redirect=None)) after connection broken by 'NewConnectionError('<telegram.vendor.ptb_urllib3.urllib3.connection.VerifiedHTTPSConnection object at 0x0000026A98FCFA00>: Failed to establish a new connection: [Errno 11001] getaddrinfo failed')': /bot1962228157:AAFEnQahitcgf3WyttR3ZpdUiBLWLQtU0WY/getUpdates
2021-09-14 14:06:35,088 - telegram.ext.updater - ERROR - Error while getting Updates: urllib3 HTTPError HTTPSConnectionPool(host='api.telegram.org', port=443): Max retries exceeded with url: /bot1962228157:AAFEnQahitcgf3WyttR3ZpdUiBLWLQtU0WY/getUpdates (Caused by NewConnectionError('<telegram.vendor.ptb_urllib3.urllib3.connection.VerifiedHTTPSConnection object at 0x0000026A98FCFB50>: Failed to establish a new connection: [Errno 11001] getaddrinfo failed'))
2021-09-14 14:06:35,088 - telegram.ext.dispatcher - ERROR - No error handlers are registered, logging exception.
Traceback (most recent call last):
  File "C:\Users\user\AppData\Local\Programs\Python\Python39\lib\site-packages\telegram\vendor\ptb_urllib3\urllib3\connection.py", line 140, in _new_conn
    conn = connection.create_connection(
  File "C:\Users\user\AppData\Local\Programs\Python\Python39\lib\site-packages\telegram\vendor\ptb_urllib3\urllib3\util\connection.py", line 60, in create_connection
    for res in socket.getaddrinfo(host, port, family, socket.SOCK_STREAM):
  File "C:\Users\user\AppData\Local\Programs\Python\Python39\lib\socket.py", line 954, in getaddrinfo
    for res in _socket.getaddrinfo(host, port, family, type, proto, flags):
socket.gaierror: [Errno 11001] getaddrinfo failed

During handling of the above exception, another exception occurred:

Traceback (most recent call last):
  File "C:\Users\user\AppData\Local\Programs\Python\Python39\lib\site-packages\telegram\vendor\ptb_urllib3\urllib3\connectionpool.py", line 614, in urlopen
    httplib_response = self._make_request(conn, method, url,
  File "C:\Users\user\AppData\Local\Programs\Python\Python39\lib\site-packages\telegram\vendor\ptb_urllib3\urllib3\connectionpool.py", line 360, in _make_request
    self._validate_conn(conn)
  File "C:\Users\user\AppData\Local\Programs\Python\Python39\lib\site-packages\telegram\vendor\ptb_urllib3\urllib3\connectionpool.py", line 857, in _validate_conn
    super(HTTPSConnectionPool, self)._validate_conn(conn)
  File "C:\Users\user\AppData\Local\Programs\Python\Python39\lib\site-packages\telegram\vendor\ptb_urllib3\urllib3\connectionpool.py", line 289, in _validate_conn
    conn.connect()
  File "C:\Users\user\AppData\Local\Programs\Python\Python39\lib\site-packages\telegram\vendor\ptb_urllib3\urllib3\connection.py", line 284, in connect
    conn = self._new_conn()
  File "C:\Users\user\AppData\Local\Programs\Python\Python39\lib\site-packages\telegram\vendor\ptb_urllib3\urllib3\connection.py", line 149, in _new_conn
    raise NewConnectionError(
telegram.vendor.ptb_urllib3.urllib3.exceptions.NewConnectionError: <telegram.vendor.ptb_urllib3.urllib3.connection.VerifiedHTTPSConnection object at 0x0000026A98FCFB50>: Failed to establish a new connection: [Errno 11001] getaddrinfo failed

During handling of the above exception, another exception occurred:

Traceback (most recent call last):
  File "C:\Users\user\AppData\Local\Programs\Python\Python39\lib\site-packages\telegram\utils\request.py", line 259, in _request_wrapper
    resp = self._con_pool.request(*args, **kwargs)
  File "C:\Users\user\AppData\Local\Programs\Python\Python39\lib\site-packages\telegram\vendor\ptb_urllib3\urllib3\request.py", line 68, in request
    return self.request_encode_body(method, url, fields=fields,
  File "C:\Users\user\AppData\Local\Programs\Python\Python39\lib\site-packages\telegram\vendor\ptb_urllib3\urllib3\request.py", line 148, in request_encode_body
    return self.urlopen(method, url, **extra_kw)
  File "C:\Users\user\AppData\Local\Programs\Python\Python39\lib\site-packages\telegram\vendor\ptb_urllib3\urllib3\poolmanager.py", line 244, in urlopen
    response = conn.urlopen(method, u.request_uri, **kw)
  File "C:\Users\user\AppData\Local\Programs\Python\Python39\lib\site-packages\telegram\vendor\ptb_urllib3\urllib3\connectionpool.py", line 691, in urlopen
    return self.urlopen(method, url, body, headers, retries,
  File "C:\Users\user\AppData\Local\Programs\Python\Python39\lib\site-packages\telegram\vendor\ptb_urllib3\urllib3\connectionpool.py", line 691, in urlopen
    return self.urlopen(method, url, body, headers, retries,
  File "C:\Users\user\AppData\Local\Programs\Python\Python39\lib\site-packages\telegram\vendor\ptb_urllib3\urllib3\connectionpool.py", line 691, in urlopen
    return self.urlopen(method, url, body, headers, retries,
  File "C:\Users\user\AppData\Local\Programs\Python\Python39\lib\site-packages\telegram\vendor\ptb_urllib3\urllib3\connectionpool.py", line 665, in urlopen
    retries = retries.increment(method, url, error=e, _pool=self,
  File "C:\Users\user\AppData\Local\Programs\Python\Python39\lib\site-packages\telegram\vendor\ptb_urllib3\urllib3\util\retry.py", line 376, in increment
    raise MaxRetryError(_pool, url, error or ResponseError(cause))
telegram.vendor.ptb_urllib3.urllib3.exceptions.MaxRetryError: HTTPSConnectionPool(host='api.telegram.org', port=443): Max retries exceeded with url: /bot1962228157:AAFEnQahitcgf3WyttR3ZpdUiBLWLQtU0WY/getUpdates (Caused by NewConnectionError('<telegram.vendor.ptb_urllib3.urllib3.connection.VerifiedHTTPSConnection object at 0x0000026A98FCFB50>: Failed to establish a new connection: [Errno 11001] getaddrinfo failed'))

The above exception was the direct cause of the following exception:

Traceback (most recent call last):
  File "C:\Users\user\AppData\Local\Programs\Python\Python39\lib\site-packages\telegram\ext\updater.py", line 646, in _network_loop_retry
    if not action_cb():
  File "C:\Users\user\AppData\Local\Programs\Python\Python39\lib\site-packages\telegram\ext\updater.py", line 597, in polling_action_cb
    updates = self.bot.get_updates(
  File "C:\Users\user\AppData\Local\Programs\Python\Python39\lib\site-packages\telegram\ext\extbot.py", line 222, in get_updates
    updates = super().get_updates(
  File "C:\Users\user\AppData\Local\Programs\Python\Python39\lib\site-packages\telegram\bot.py", line 130, in decorator
    result = func(*args, **kwargs)
  File "C:\Users\user\AppData\Local\Programs\Python\Python39\lib\site-packages\telegram\bot.py", line 2861, in get_updates
    self._post(
  File "C:\Users\user\AppData\Local\Programs\Python\Python39\lib\site-packages\telegram\bot.py", line 295, in _post
    return self.request.post(
  File "C:\Users\user\AppData\Local\Programs\Python\Python39\lib\site-packages\telegram\utils\request.py", line 356, in post
    result = self._request_wrapper(
  File "C:\Users\user\AppData\Local\Programs\Python\Python39\lib\site-packages\telegram\utils\request.py", line 265, in _request_wrapper
    raise NetworkError(f'urllib3 HTTPError {error}') from error
telegram.error.NetworkError: urllib3 HTTPError HTTPSConnectionPool(host='api.telegram.org', port=443): Max retries exceeded with url: /bot1962228157:AAFEnQahitcgf3WyttR3ZpdUiBLWLQtU0WY/getUpdates (Caused by NewConnectionError('<telegram.vendor.ptb_urllib3.urllib3.connection.VerifiedHTTPSConnection object at 0x0000026A98FCFB50>: Failed to establish a new connection: [Errno 11001] getaddrinfo failed'))
2021-09-14 14:06:36,589 - telegram.vendor.ptb_urllib3.urllib3.connectionpool - WARNING - Retrying (Retry(total=2, connect=None, read=None, redirect=None)) after connection broken by 'NewConnectionError('<telegram.vendor.ptb_urllib3.urllib3.connection.VerifiedHTTPSConnection object at 0x0000026A98FCF370>: Failed to establish a new connection: [Errno 11001] getaddrinfo failed')': /bot1962228157:AAFEnQahitcgf3WyttR3ZpdUiBLWLQtU0WY/getUpdates
2021-09-14 14:06:36,590 - telegram.vendor.ptb_urllib3.urllib3.connectionpool - WARNING - Retrying (Retry(total=1, connect=None, read=None, redirect=None)) after connection broken by 'NewConnectionError('<telegram.vendor.ptb_urllib3.urllib3.connection.VerifiedHTTPSConnection object at 0x0000026A98FCFD00>: Failed to establish a new connection: [Errno 11001] getaddrinfo failed')': /bot1962228157:AAFEnQahitcgf3WyttR3ZpdUiBLWLQtU0WY/getUpdates
2021-09-14 14:06:36,591 - telegram.vendor.ptb_urllib3.urllib3.connectionpool - WARNING - Retrying (Retry(total=0, connect=None, read=None, redirect=None)) after connection broken by 'NewConnectionError('<telegram.vendor.ptb_urllib3.urllib3.connection.VerifiedHTTPSConnection object at 0x0000026A98FCFE50>: Failed to establish a new connection: [Errno 11001] getaddrinfo failed')': /bot1962228157:AAFEnQahitcgf3WyttR3ZpdUiBLWLQtU0WY/getUpdates
2021-09-14 14:06:36,591 - telegram.ext.updater - ERROR - Error while getting Updates: urllib3 HTTPError HTTPSConnectionPool(host='api.telegram.org', port=443): Max retries exceeded with url: /bot1962228157:AAFEnQahitcgf3WyttR3ZpdUiBLWLQtU0WY/getUpdates (Caused by NewConnectionError('<telegram.vendor.ptb_urllib3.urllib3.connection.VerifiedHTTPSConnection object at 0x0000026A98FCFFA0>: Failed to establish a new connection: [Errno 11001] getaddrinfo failed'))
2021-09-14 14:06:36,592 - telegram.ext.dispatcher - ERROR - No error handlers are registered, logging exception.
Traceback (most recent call last):
  File "C:\Users\user\AppData\Local\Programs\Python\Python39\lib\site-packages\telegram\vendor\ptb_urllib3\urllib3\connection.py", line 140, in _new_conn
    conn = connection.create_connection(
  File "C:\Users\user\AppData\Local\Programs\Python\Python39\lib\site-packages\telegram\vendor\ptb_urllib3\urllib3\util\connection.py", line 60, in create_connection
    for res in socket.getaddrinfo(host, port, family, socket.SOCK_STREAM):
  File "C:\Users\user\AppData\Local\Programs\Python\Python39\lib\socket.py", line 954, in getaddrinfo
    for res in _socket.getaddrinfo(host, port, family, type, proto, flags):
socket.gaierror: [Errno 11001] getaddrinfo failed

During handling of the above exception, another exception occurred:

Traceback (most recent call last):
  File "C:\Users\user\AppData\Local\Programs\Python\Python39\lib\site-packages\telegram\vendor\ptb_urllib3\urllib3\connectionpool.py", line 614, in urlopen
    httplib_response = self._make_request(conn, method, url,
  File "C:\Users\user\AppData\Local\Programs\Python\Python39\lib\site-packages\telegram\vendor\ptb_urllib3\urllib3\connectionpool.py", line 360, in _make_request
    self._validate_conn(conn)
  File "C:\Users\user\AppData\Local\Programs\Python\Python39\lib\site-packages\telegram\vendor\ptb_urllib3\urllib3\connectionpool.py", line 857, in _validate_conn
    super(HTTPSConnectionPool, self)._validate_conn(conn)
  File "C:\Users\user\AppData\Local\Programs\Python\Python39\lib\site-packages\telegram\vendor\ptb_urllib3\urllib3\connectionpool.py", line 289, in _validate_conn
    conn.connect()
  File "C:\Users\user\AppData\Local\Programs\Python\Python39\lib\site-packages\telegram\vendor\ptb_urllib3\urllib3\connection.py", line 284, in connect
    conn = self._new_conn()
  File "C:\Users\user\AppData\Local\Programs\Python\Python39\lib\site-packages\telegram\vendor\ptb_urllib3\urllib3\connection.py", line 149, in _new_conn
    raise NewConnectionError(
telegram.vendor.ptb_urllib3.urllib3.exceptions.NewConnectionError: <telegram.vendor.ptb_urllib3.urllib3.connection.VerifiedHTTPSConnection object at 0x0000026A98FCFFA0>: Failed to establish a new connection: [Errno 11001] getaddrinfo failed

During handling of the above exception, another exception occurred:

Traceback (most recent call last):
  File "C:\Users\user\AppData\Local\Programs\Python\Python39\lib\site-packages\telegram\utils\request.py", line 259, in _request_wrapper
    resp = self._con_pool.request(*args, **kwargs)
  File "C:\Users\user\AppData\Local\Programs\Python\Python39\lib\site-packages\telegram\vendor\ptb_urllib3\urllib3\request.py", line 68, in request
    return self.request_encode_body(method, url, fields=fields,
  File "C:\Users\user\AppData\Local\Programs\Python\Python39\lib\site-packages\telegram\vendor\ptb_urllib3\urllib3\request.py", line 148, in request_encode_body
    return self.urlopen(method, url, **extra_kw)
  File "C:\Users\user\AppData\Local\Programs\Python\Python39\lib\site-packages\telegram\vendor\ptb_urllib3\urllib3\poolmanager.py", line 244, in urlopen
    response = conn.urlopen(method, u.request_uri, **kw)
  File "C:\Users\user\AppData\Local\Programs\Python\Python39\lib\site-packages\telegram\vendor\ptb_urllib3\urllib3\connectionpool.py", line 691, in urlopen
    return self.urlopen(method, url, body, headers, retries,
  File "C:\Users\user\AppData\Local\Programs\Python\Python39\lib\site-packages\telegram\vendor\ptb_urllib3\urllib3\connectionpool.py", line 691, in urlopen
    return self.urlopen(method, url, body, headers, retries,
  File "C:\Users\user\AppData\Local\Programs\Python\Python39\lib\site-packages\telegram\vendor\ptb_urllib3\urllib3\connectionpool.py", line 691, in urlopen
    return self.urlopen(method, url, body, headers, retries,
  File "C:\Users\user\AppData\Local\Programs\Python\Python39\lib\site-packages\telegram\vendor\ptb_urllib3\urllib3\connectionpool.py", line 665, in urlopen
    retries = retries.increment(method, url, error=e, _pool=self,
  File "C:\Users\user\AppData\Local\Programs\Python\Python39\lib\site-packages\telegram\vendor\ptb_urllib3\urllib3\util\retry.py", line 376, in increment
    raise MaxRetryError(_pool, url, error or ResponseError(cause))
telegram.vendor.ptb_urllib3.urllib3.exceptions.MaxRetryError: HTTPSConnectionPool(host='api.telegram.org', port=443): Max retries exceeded with url: /bot1962228157:AAFEnQahitcgf3WyttR3ZpdUiBLWLQtU0WY/getUpdates (Caused by NewConnectionError('<telegram.vendor.ptb_urllib3.urllib3.connection.VerifiedHTTPSConnection object at 0x0000026A98FCFFA0>: Failed to establish a new connection: [Errno 11001] getaddrinfo failed'))

The above exception was the direct cause of the following exception:

Traceback (most recent call last):
  File "C:\Users\user\AppData\Local\Programs\Python\Python39\lib\site-packages\telegram\ext\updater.py", line 646, in _network_loop_retry
    if not action_cb():
  File "C:\Users\user\AppData\Local\Programs\Python\Python39\lib\site-packages\telegram\ext\updater.py", line 597, in polling_action_cb
    updates = self.bot.get_updates(
  File "C:\Users\user\AppData\Local\Programs\Python\Python39\lib\site-packages\telegram\ext\extbot.py", line 222, in get_updates
    updates = super().get_updates(
  File "C:\Users\user\AppData\Local\Programs\Python\Python39\lib\site-packages\telegram\bot.py", line 130, in decorator
    result = func(*args, **kwargs)
  File "C:\Users\user\AppData\Local\Programs\Python\Python39\lib\site-packages\telegram\bot.py", line 2861, in get_updates
    self._post(
  File "C:\Users\user\AppData\Local\Programs\Python\Python39\lib\site-packages\telegram\bot.py", line 295, in _post
    return self.request.post(
  File "C:\Users\user\AppData\Local\Programs\Python\Python39\lib\site-packages\telegram\utils\request.py", line 356, in post
    result = self._request_wrapper(
  File "C:\Users\user\AppData\Local\Programs\Python\Python39\lib\site-packages\telegram\utils\request.py", line 265, in _request_wrapper
    raise NetworkError(f'urllib3 HTTPError {error}') from error
telegram.error.NetworkError: urllib3 HTTPError HTTPSConnectionPool(host='api.telegram.org', port=443): Max retries exceeded with url: /bot1962228157:AAFEnQahitcgf3WyttR3ZpdUiBLWLQtU0WY/getUpdates (Caused by NewConnectionError('<telegram.vendor.ptb_urllib3.urllib3.connection.VerifiedHTTPSConnection object at 0x0000026A98FCFFA0>: Failed to establish a new connection: [Errno 11001] getaddrinfo failed'))
2021-09-14 14:06:38,842 - telegram.vendor.ptb_urllib3.urllib3.connectionpool - WARNING - Retrying (Retry(total=2, connect=None, read=None, redirect=None)) after connection broken by 'NewConnectionError('<telegram.vendor.ptb_urllib3.urllib3.connection.VerifiedHTTPSConnection object at 0x0000026A98FCFC40>: Failed to establish a new connection: [Errno 11001] getaddrinfo failed')': /bot1962228157:AAFEnQahitcgf3WyttR3ZpdUiBLWLQtU0WY/getUpdates
2021-09-14 14:06:38,843 - telegram.vendor.ptb_urllib3.urllib3.connectionpool - WARNING - Retrying (Retry(total=1, connect=None, read=None, redirect=None)) after connection broken by 'NewConnectionError('<telegram.vendor.ptb_urllib3.urllib3.connection.VerifiedHTTPSConnection object at 0x0000026A990CE190>: Failed to establish a new connection: [Errno 11001] getaddrinfo failed')': /bot1962228157:AAFEnQahitcgf3WyttR3ZpdUiBLWLQtU0WY/getUpdates
2021-09-14 14:06:38,843 - telegram.vendor.ptb_urllib3.urllib3.connectionpool - WARNING - Retrying (Retry(total=0, connect=None, read=None, redirect=None)) after connection broken by 'NewConnectionError('<telegram.vendor.ptb_urllib3.urllib3.connection.VerifiedHTTPSConnection object at 0x0000026A990CE2E0>: Failed to establish a new connection: [Errno 11001] getaddrinfo failed')': /bot1962228157:AAFEnQahitcgf3WyttR3ZpdUiBLWLQtU0WY/getUpdates
2021-09-14 14:06:38,843 - telegram.ext.updater - ERROR - Error while getting Updates: urllib3 HTTPError HTTPSConnectionPool(host='api.telegram.org', port=443): Max retries exceeded with url: /bot1962228157:AAFEnQahitcgf3WyttR3ZpdUiBLWLQtU0WY/getUpdates (Caused by NewConnectionError('<telegram.vendor.ptb_urllib3.urllib3.connection.VerifiedHTTPSConnection object at 0x0000026A990CE430>: Failed to establish a new connection: [Errno 11001] getaddrinfo failed'))
2021-09-14 14:06:38,843 - telegram.ext.dispatcher - ERROR - No error handlers are registered, logging exception.
Traceback (most recent call last):
  File "C:\Users\user\AppData\Local\Programs\Python\Python39\lib\site-packages\telegram\vendor\ptb_urllib3\urllib3\connection.py", line 140, in _new_conn
    conn = connection.create_connection(
  File "C:\Users\user\AppData\Local\Programs\Python\Python39\lib\site-packages\telegram\vendor\ptb_urllib3\urllib3\util\connection.py", line 60, in create_connection
    for res in socket.getaddrinfo(host, port, family, socket.SOCK_STREAM):
  File "C:\Users\user\AppData\Local\Programs\Python\Python39\lib\socket.py", line 954, in getaddrinfo
    for res in _socket.getaddrinfo(host, port, family, type, proto, flags):
socket.gaierror: [Errno 11001] getaddrinfo failed

During handling of the above exception, another exception occurred:

Traceback (most recent call last):
  File "C:\Users\user\AppData\Local\Programs\Python\Python39\lib\site-packages\telegram\vendor\ptb_urllib3\urllib3\connectionpool.py", line 614, in urlopen
    httplib_response = self._make_request(conn, method, url,
  File "C:\Users\user\AppData\Local\Programs\Python\Python39\lib\site-packages\telegram\vendor\ptb_urllib3\urllib3\connectionpool.py", line 360, in _make_request
    self._validate_conn(conn)
  File "C:\Users\user\AppData\Local\Programs\Python\Python39\lib\site-packages\telegram\vendor\ptb_urllib3\urllib3\connectionpool.py", line 857, in _validate_conn
    super(HTTPSConnectionPool, self)._validate_conn(conn)
  File "C:\Users\user\AppData\Local\Programs\Python\Python39\lib\site-packages\telegram\vendor\ptb_urllib3\urllib3\connectionpool.py", line 289, in _validate_conn
    conn.connect()
  File "C:\Users\user\AppData\Local\Programs\Python\Python39\lib\site-packages\telegram\vendor\ptb_urllib3\urllib3\connection.py", line 284, in connect
    conn = self._new_conn()
  File "C:\Users\user\AppData\Local\Programs\Python\Python39\lib\site-packages\telegram\vendor\ptb_urllib3\urllib3\connection.py", line 149, in _new_conn
    raise NewConnectionError(
telegram.vendor.ptb_urllib3.urllib3.exceptions.NewConnectionError: <telegram.vendor.ptb_urllib3.urllib3.connection.VerifiedHTTPSConnection object at 0x0000026A990CE430>: Failed to establish a new connection: [Errno 11001] getaddrinfo failed

During handling of the above exception, another exception occurred:

Traceback (most recent call last):
  File "C:\Users\user\AppData\Local\Programs\Python\Python39\lib\site-packages\telegram\utils\request.py", line 259, in _request_wrapper
    resp = self._con_pool.request(*args, **kwargs)
  File "C:\Users\user\AppData\Local\Programs\Python\Python39\lib\site-packages\telegram\vendor\ptb_urllib3\urllib3\request.py", line 68, in request
    return self.request_encode_body(method, url, fields=fields,
  File "C:\Users\user\AppData\Local\Programs\Python\Python39\lib\site-packages\telegram\vendor\ptb_urllib3\urllib3\request.py", line 148, in request_encode_body
    return self.urlopen(method, url, **extra_kw)
  File "C:\Users\user\AppData\Local\Programs\Python\Python39\lib\site-packages\telegram\vendor\ptb_urllib3\urllib3\poolmanager.py", line 244, in urlopen
    response = conn.urlopen(method, u.request_uri, **kw)
  File "C:\Users\user\AppData\Local\Programs\Python\Python39\lib\site-packages\telegram\vendor\ptb_urllib3\urllib3\connectionpool.py", line 691, in urlopen
    return self.urlopen(method, url, body, headers, retries,
  File "C:\Users\user\AppData\Local\Programs\Python\Python39\lib\site-packages\telegram\vendor\ptb_urllib3\urllib3\connectionpool.py", line 691, in urlopen
    return self.urlopen(method, url, body, headers, retries,
  File "C:\Users\user\AppData\Local\Programs\Python\Python39\lib\site-packages\telegram\vendor\ptb_urllib3\urllib3\connectionpool.py", line 691, in urlopen
    return self.urlopen(method, url, body, headers, retries,
  File "C:\Users\user\AppData\Local\Programs\Python\Python39\lib\site-packages\telegram\vendor\ptb_urllib3\urllib3\connectionpool.py", line 665, in urlopen
    retries = retries.increment(method, url, error=e, _pool=self,
  File "C:\Users\user\AppData\Local\Programs\Python\Python39\lib\site-packages\telegram\vendor\ptb_urllib3\urllib3\util\retry.py", line 376, in increment
    raise MaxRetryError(_pool, url, error or ResponseError(cause))
telegram.vendor.ptb_urllib3.urllib3.exceptions.MaxRetryError: HTTPSConnectionPool(host='api.telegram.org', port=443): Max retries exceeded with url: /bot1962228157:AAFEnQahitcgf3WyttR3ZpdUiBLWLQtU0WY/getUpdates (Caused by NewConnectionError('<telegram.vendor.ptb_urllib3.urllib3.connection.VerifiedHTTPSConnection object at 0x0000026A990CE430>: Failed to establish a new connection: [Errno 11001] getaddrinfo failed'))

The above exception was the direct cause of the following exception:

Traceback (most recent call last):
  File "C:\Users\user\AppData\Local\Programs\Python\Python39\lib\site-packages\telegram\ext\updater.py", line 646, in _network_loop_retry
    if not action_cb():
  File "C:\Users\user\AppData\Local\Programs\Python\Python39\lib\site-packages\telegram\ext\updater.py", line 597, in polling_action_cb
    updates = self.bot.get_updates(
  File "C:\Users\user\AppData\Local\Programs\Python\Python39\lib\site-packages\telegram\ext\extbot.py", line 222, in get_updates
    updates = super().get_updates(
  File "C:\Users\user\AppData\Local\Programs\Python\Python39\lib\site-packages\telegram\bot.py", line 130, in decorator
    result = func(*args, **kwargs)
  File "C:\Users\user\AppData\Local\Programs\Python\Python39\lib\site-packages\telegram\bot.py", line 2861, in get_updates
    self._post(
  File "C:\Users\user\AppData\Local\Programs\Python\Python39\lib\site-packages\telegram\bot.py", line 295, in _post
    return self.request.post(
  File "C:\Users\user\AppData\Local\Programs\Python\Python39\lib\site-packages\telegram\utils\request.py", line 356, in post
    result = self._request_wrapper(
  File "C:\Users\user\AppData\Local\Programs\Python\Python39\lib\site-packages\telegram\utils\request.py", line 265, in _request_wrapper
    raise NetworkError(f'urllib3 HTTPError {error}') from error
telegram.error.NetworkError: urllib3 HTTPError HTTPSConnectionPool(host='api.telegram.org', port=443): Max retries exceeded with url: /bot1962228157:AAFEnQahitcgf3WyttR3ZpdUiBLWLQtU0WY/getUpdates (Caused by NewConnectionError('<telegram.vendor.ptb_urllib3.urllib3.connection.VerifiedHTTPSConnection object at 0x0000026A990CE430>: Failed to establish a new connection: [Errno 11001] getaddrinfo failed'))
2021-09-14 14:06:42,575 - root - INFO - b'/'
2021-09-14 14:06:52,313 - root - INFO - b'\xd0\xbf\xd1\x80\xd0\xb8\xd0\xb2\xd0\xb5\xd1\x82'
2021-09-14 14:11:33,623 - root - INFO - Bot started...
2021-09-14 14:11:33,624 - apscheduler.scheduler - INFO - Scheduler started
2021-09-14 14:11:42,698 - root - INFO - b'\xd0\x9f\xd1\x80\xd0\xb8\xd0\xb2\xd0\xb5\xd1\x82'
2021-09-14 14:12:56,311 - root - INFO - Bot started...
2021-09-14 14:12:56,311 - apscheduler.scheduler - INFO - Scheduler started
2021-09-14 14:13:07,229 - root - INFO - œË‚ÂÚ
2021-09-14 14:13:45,656 - root - INFO - œË‚ÂÚ
2021-09-15 09:15:07,429 - root - INFO - Bot started...
2021-09-15 09:15:07,530 - apscheduler.scheduler - INFO - Scheduler started
2021-09-15 09:15:55,950 - root - INFO - œË‚ÂÚ!
 ‡Í ‰ÂÎ‡?
2021-09-15 09:24:58,318 - root - INFO - Bot started...
2021-09-15 09:26:07,025 - root - INFO - Bot started...
2021-09-15 09:26:07,033 - apscheduler.scheduler - INFO - Scheduler started
2021-09-15 09:26:14,660 - root - INFO - ÔË‚ÂÚ
2021-09-15 09:27:02,377 - root - INFO - Bot started...
2021-09-15 09:27:02,377 - apscheduler.scheduler - INFO - Scheduler started
2021-09-15 09:59:34,082 - root - INFO - Bot started...
2021-09-15 09:59:34,087 - apscheduler.scheduler - INFO - Scheduler started
2021-09-15 09:59:34,717 - telegram.ext.updater - ERROR - Error while getting Updates: Conflict: terminated by other getUpdates request; make sure that only one bot instance is running
2021-09-15 09:59:34,717 - telegram.ext.dispatcher - ERROR - No error handlers are registered, logging exception.
Traceback (most recent call last):
  File "C:\Users\user\AppData\Local\Programs\Python\Python39\lib\site-packages\telegram\ext\updater.py", line 646, in _network_loop_retry
    if not action_cb():
  File "C:\Users\user\AppData\Local\Programs\Python\Python39\lib\site-packages\telegram\ext\updater.py", line 597, in polling_action_cb
    updates = self.bot.get_updates(
  File "C:\Users\user\AppData\Local\Programs\Python\Python39\lib\site-packages\telegram\ext\extbot.py", line 222, in get_updates
    updates = super().get_updates(
  File "C:\Users\user\AppData\Local\Programs\Python\Python39\lib\site-packages\telegram\bot.py", line 130, in decorator
    result = func(*args, **kwargs)
  File "C:\Users\user\AppData\Local\Programs\Python\Python39\lib\site-packages\telegram\bot.py", line 2861, in get_updates
    self._post(
  File "C:\Users\user\AppData\Local\Programs\Python\Python39\lib\site-packages\telegram\bot.py", line 295, in _post
    return self.request.post(
  File "C:\Users\user\AppData\Local\Programs\Python\Python39\lib\site-packages\telegram\utils\request.py", line 356, in post
    result = self._request_wrapper(
  File "C:\Users\user\AppData\Local\Programs\Python\Python39\lib\site-packages\telegram\utils\request.py", line 283, in _request_wrapper
    raise Conflict(message)
telegram.error.Conflict: Conflict: terminated by other getUpdates request; make sure that only one bot instance is running
2021-09-15 09:59:38,828 - telegram.ext.updater - ERROR - Error while getting Updates: Conflict: terminated by other getUpdates request; make sure that only one bot instance is running
2021-09-15 09:59:38,828 - telegram.ext.dispatcher - ERROR - No error handlers are registered, logging exception.
Traceback (most recent call last):
  File "C:\Users\user\AppData\Local\Programs\Python\Python39\lib\site-packages\telegram\ext\updater.py", line 646, in _network_loop_retry
    if not action_cb():
  File "C:\Users\user\AppData\Local\Programs\Python\Python39\lib\site-packages\telegram\ext\updater.py", line 597, in polling_action_cb
    updates = self.bot.get_updates(
  File "C:\Users\user\AppData\Local\Programs\Python\Python39\lib\site-packages\telegram\ext\extbot.py", line 222, in get_updates
    updates = super().get_updates(
  File "C:\Users\user\AppData\Local\Programs\Python\Python39\lib\site-packages\telegram\bot.py", line 130, in decorator
    result = func(*args, **kwargs)
  File "C:\Users\user\AppData\Local\Programs\Python\Python39\lib\site-packages\telegram\bot.py", line 2861, in get_updates
    self._post(
  File "C:\Users\user\AppData\Local\Programs\Python\Python39\lib\site-packages\telegram\bot.py", line 295, in _post
    return self.request.post(
  File "C:\Users\user\AppData\Local\Programs\Python\Python39\lib\site-packages\telegram\utils\request.py", line 356, in post
    result = self._request_wrapper(
  File "C:\Users\user\AppData\Local\Programs\Python\Python39\lib\site-packages\telegram\utils\request.py", line 283, in _request_wrapper
    raise Conflict(message)
telegram.error.Conflict: Conflict: terminated by other getUpdates request; make sure that only one bot instance is running
2021-09-15 09:59:39,933 - telegram.ext.updater - ERROR - Error while getting Updates: Conflict: terminated by other getUpdates request; make sure that only one bot instance is running
2021-09-15 09:59:39,933 - telegram.ext.dispatcher - ERROR - No error handlers are registered, logging exception.
Traceback (most recent call last):
  File "C:\Users\user\AppData\Local\Programs\Python\Python39\lib\site-packages\telegram\ext\updater.py", line 646, in _network_loop_retry
    if not action_cb():
  File "C:\Users\user\AppData\Local\Programs\Python\Python39\lib\site-packages\telegram\ext\updater.py", line 597, in polling_action_cb
    updates = self.bot.get_updates(
  File "C:\Users\user\AppData\Local\Programs\Python\Python39\lib\site-packages\telegram\ext\extbot.py", line 222, in get_updates
    updates = super().get_updates(
  File "C:\Users\user\AppData\Local\Programs\Python\Python39\lib\site-packages\telegram\bot.py", line 130, in decorator
    result = func(*args, **kwargs)
  File "C:\Users\user\AppData\Local\Programs\Python\Python39\lib\site-packages\telegram\bot.py", line 2861, in get_updates
    self._post(
  File "C:\Users\user\AppData\Local\Programs\Python\Python39\lib\site-packages\telegram\bot.py", line 295, in _post
    return self.request.post(
  File "C:\Users\user\AppData\Local\Programs\Python\Python39\lib\site-packages\telegram\utils\request.py", line 356, in post
    result = self._request_wrapper(
  File "C:\Users\user\AppData\Local\Programs\Python\Python39\lib\site-packages\telegram\utils\request.py", line 283, in _request_wrapper
    raise Conflict(message)
telegram.error.Conflict: Conflict: terminated by other getUpdates request; make sure that only one bot instance is running
2021-09-15 09:59:44,537 - telegram.ext.updater - ERROR - Error while getting Updates: Conflict: terminated by other getUpdates request; make sure that only one bot instance is running
2021-09-15 09:59:44,537 - telegram.ext.dispatcher - ERROR - No error handlers are registered, logging exception.
Traceback (most recent call last):
  File "C:\Users\user\AppData\Local\Programs\Python\Python39\lib\site-packages\telegram\ext\updater.py", line 646, in _network_loop_retry
    if not action_cb():
  File "C:\Users\user\AppData\Local\Programs\Python\Python39\lib\site-packages\telegram\ext\updater.py", line 597, in polling_action_cb
    updates = self.bot.get_updates(
  File "C:\Users\user\AppData\Local\Programs\Python\Python39\lib\site-packages\telegram\ext\extbot.py", line 222, in get_updates
    updates = super().get_updates(
  File "C:\Users\user\AppData\Local\Programs\Python\Python39\lib\site-packages\telegram\bot.py", line 130, in decorator
    result = func(*args, **kwargs)
  File "C:\Users\user\AppData\Local\Programs\Python\Python39\lib\site-packages\telegram\bot.py", line 2861, in get_updates
    self._post(
  File "C:\Users\user\AppData\Local\Programs\Python\Python39\lib\site-packages\telegram\bot.py", line 295, in _post
    return self.request.post(
  File "C:\Users\user\AppData\Local\Programs\Python\Python39\lib\site-packages\telegram\utils\request.py", line 356, in post
    result = self._request_wrapper(
  File "C:\Users\user\AppData\Local\Programs\Python\Python39\lib\site-packages\telegram\utils\request.py", line 283, in _request_wrapper
    raise Conflict(message)
telegram.error.Conflict: Conflict: terminated by other getUpdates request; make sure that only one bot instance is running
2021-09-15 09:59:46,140 - telegram.ext.updater - ERROR - Error while getting Updates: Conflict: terminated by other getUpdates request; make sure that only one bot instance is running
2021-09-15 09:59:46,140 - telegram.ext.dispatcher - ERROR - No error handlers are registered, logging exception.
Traceback (most recent call last):
  File "C:\Users\user\AppData\Local\Programs\Python\Python39\lib\site-packages\telegram\ext\updater.py", line 646, in _network_loop_retry
    if not action_cb():
  File "C:\Users\user\AppData\Local\Programs\Python\Python39\lib\site-packages\telegram\ext\updater.py", line 597, in polling_action_cb
    updates = self.bot.get_updates(
  File "C:\Users\user\AppData\Local\Programs\Python\Python39\lib\site-packages\telegram\ext\extbot.py", line 222, in get_updates
    updates = super().get_updates(
  File "C:\Users\user\AppData\Local\Programs\Python\Python39\lib\site-packages\telegram\bot.py", line 130, in decorator
    result = func(*args, **kwargs)
  File "C:\Users\user\AppData\Local\Programs\Python\Python39\lib\site-packages\telegram\bot.py", line 2861, in get_updates
    self._post(
  File "C:\Users\user\AppData\Local\Programs\Python\Python39\lib\site-packages\telegram\bot.py", line 295, in _post
    return self.request.post(
  File "C:\Users\user\AppData\Local\Programs\Python\Python39\lib\site-packages\telegram\utils\request.py", line 356, in post
    result = self._request_wrapper(
  File "C:\Users\user\AppData\Local\Programs\Python\Python39\lib\site-packages\telegram\utils\request.py", line 283, in _request_wrapper
    raise Conflict(message)
telegram.error.Conflict: Conflict: terminated by other getUpdates request; make sure that only one bot instance is running
2021-09-15 09:59:50,241 - telegram.ext.updater - ERROR - Error while getting Updates: Conflict: terminated by other getUpdates request; make sure that only one bot instance is running
2021-09-15 09:59:50,241 - telegram.ext.dispatcher - ERROR - No error handlers are registered, logging exception.
Traceback (most recent call last):
  File "C:\Users\user\AppData\Local\Programs\Python\Python39\lib\site-packages\telegram\ext\updater.py", line 646, in _network_loop_retry
    if not action_cb():
  File "C:\Users\user\AppData\Local\Programs\Python\Python39\lib\site-packages\telegram\ext\updater.py", line 597, in polling_action_cb
    updates = self.bot.get_updates(
  File "C:\Users\user\AppData\Local\Programs\Python\Python39\lib\site-packages\telegram\ext\extbot.py", line 222, in get_updates
    updates = super().get_updates(
  File "C:\Users\user\AppData\Local\Programs\Python\Python39\lib\site-packages\telegram\bot.py", line 130, in decorator
    result = func(*args, **kwargs)
  File "C:\Users\user\AppData\Local\Programs\Python\Python39\lib\site-packages\telegram\bot.py", line 2861, in get_updates
    self._post(
  File "C:\Users\user\AppData\Local\Programs\Python\Python39\lib\site-packages\telegram\bot.py", line 295, in _post
    return self.request.post(
  File "C:\Users\user\AppData\Local\Programs\Python\Python39\lib\site-packages\telegram\utils\request.py", line 356, in post
    result = self._request_wrapper(
  File "C:\Users\user\AppData\Local\Programs\Python\Python39\lib\site-packages\telegram\utils\request.py", line 283, in _request_wrapper
    raise Conflict(message)
telegram.error.Conflict: Conflict: terminated by other getUpdates request; make sure that only one bot instance is running
2021-09-15 09:59:52,588 - telegram.ext.updater - ERROR - Error while getting Updates: Conflict: terminated by other getUpdates request; make sure that only one bot instance is running
2021-09-15 09:59:52,588 - telegram.ext.dispatcher - ERROR - No error handlers are registered, logging exception.
Traceback (most recent call last):
  File "C:\Users\user\AppData\Local\Programs\Python\Python39\lib\site-packages\telegram\ext\updater.py", line 646, in _network_loop_retry
    if not action_cb():
  File "C:\Users\user\AppData\Local\Programs\Python\Python39\lib\site-packages\telegram\ext\updater.py", line 597, in polling_action_cb
    updates = self.bot.get_updates(
  File "C:\Users\user\AppData\Local\Programs\Python\Python39\lib\site-packages\telegram\ext\extbot.py", line 222, in get_updates
    updates = super().get_updates(
  File "C:\Users\user\AppData\Local\Programs\Python\Python39\lib\site-packages\telegram\bot.py", line 130, in decorator
    result = func(*args, **kwargs)
  File "C:\Users\user\AppData\Local\Programs\Python\Python39\lib\site-packages\telegram\bot.py", line 2861, in get_updates
    self._post(
  File "C:\Users\user\AppData\Local\Programs\Python\Python39\lib\site-packages\telegram\bot.py", line 295, in _post
    return self.request.post(
  File "C:\Users\user\AppData\Local\Programs\Python\Python39\lib\site-packages\telegram\utils\request.py", line 356, in post
    result = self._request_wrapper(
  File "C:\Users\user\AppData\Local\Programs\Python\Python39\lib\site-packages\telegram\utils\request.py", line 283, in _request_wrapper
    raise Conflict(message)
telegram.error.Conflict: Conflict: terminated by other getUpdates request; make sure that only one bot instance is running
2021-09-15 09:59:57,411 - telegram.ext.updater - ERROR - Error while getting Updates: Conflict: terminated by other getUpdates request; make sure that only one bot instance is running
2021-09-15 09:59:57,411 - telegram.ext.dispatcher - ERROR - No error handlers are registered, logging exception.
Traceback (most recent call last):
  File "C:\Users\user\AppData\Local\Programs\Python\Python39\lib\site-packages\telegram\ext\updater.py", line 646, in _network_loop_retry
    if not action_cb():
  File "C:\Users\user\AppData\Local\Programs\Python\Python39\lib\site-packages\telegram\ext\updater.py", line 597, in polling_action_cb
    updates = self.bot.get_updates(
  File "C:\Users\user\AppData\Local\Programs\Python\Python39\lib\site-packages\telegram\ext\extbot.py", line 222, in get_updates
    updates = super().get_updates(
  File "C:\Users\user\AppData\Local\Programs\Python\Python39\lib\site-packages\telegram\bot.py", line 130, in decorator
    result = func(*args, **kwargs)
  File "C:\Users\user\AppData\Local\Programs\Python\Python39\lib\site-packages\telegram\bot.py", line 2861, in get_updates
    self._post(
  File "C:\Users\user\AppData\Local\Programs\Python\Python39\lib\site-packages\telegram\bot.py", line 295, in _post
    return self.request.post(
  File "C:\Users\user\AppData\Local\Programs\Python\Python39\lib\site-packages\telegram\utils\request.py", line 356, in post
    result = self._request_wrapper(
  File "C:\Users\user\AppData\Local\Programs\Python\Python39\lib\site-packages\telegram\utils\request.py", line 283, in _request_wrapper
    raise Conflict(message)
telegram.error.Conflict: Conflict: terminated by other getUpdates request; make sure that only one bot instance is running
2021-09-15 10:00:00,883 - telegram.ext.updater - ERROR - Error while getting Updates: Conflict: terminated by other getUpdates request; make sure that only one bot instance is running
2021-09-15 10:00:00,883 - telegram.ext.dispatcher - ERROR - No error handlers are registered, logging exception.
Traceback (most recent call last):
  File "C:\Users\user\AppData\Local\Programs\Python\Python39\lib\site-packages\telegram\ext\updater.py", line 646, in _network_loop_retry
    if not action_cb():
  File "C:\Users\user\AppData\Local\Programs\Python\Python39\lib\site-packages\telegram\ext\updater.py", line 597, in polling_action_cb
    updates = self.bot.get_updates(
  File "C:\Users\user\AppData\Local\Programs\Python\Python39\lib\site-packages\telegram\ext\extbot.py", line 222, in get_updates
    updates = super().get_updates(
  File "C:\Users\user\AppData\Local\Programs\Python\Python39\lib\site-packages\telegram\bot.py", line 130, in decorator
    result = func(*args, **kwargs)
  File "C:\Users\user\AppData\Local\Programs\Python\Python39\lib\site-packages\telegram\bot.py", line 2861, in get_updates
    self._post(
  File "C:\Users\user\AppData\Local\Programs\Python\Python39\lib\site-packages\telegram\bot.py", line 295, in _post
    return self.request.post(
  File "C:\Users\user\AppData\Local\Programs\Python\Python39\lib\site-packages\telegram\utils\request.py", line 356, in post
    result = self._request_wrapper(
  File "C:\Users\user\AppData\Local\Programs\Python\Python39\lib\site-packages\telegram\utils\request.py", line 283, in _request_wrapper
    raise Conflict(message)
telegram.error.Conflict: Conflict: terminated by other getUpdates request; make sure that only one bot instance is running
2021-09-15 10:00:06,242 - telegram.ext.updater - ERROR - Error while getting Updates: Conflict: terminated by other getUpdates request; make sure that only one bot instance is running
2021-09-15 10:00:06,243 - telegram.ext.dispatcher - ERROR - No error handlers are registered, logging exception.
Traceback (most recent call last):
  File "C:\Users\user\AppData\Local\Programs\Python\Python39\lib\site-packages\telegram\ext\updater.py", line 646, in _network_loop_retry
    if not action_cb():
  File "C:\Users\user\AppData\Local\Programs\Python\Python39\lib\site-packages\telegram\ext\updater.py", line 597, in polling_action_cb
    updates = self.bot.get_updates(
  File "C:\Users\user\AppData\Local\Programs\Python\Python39\lib\site-packages\telegram\ext\extbot.py", line 222, in get_updates
    updates = super().get_updates(
  File "C:\Users\user\AppData\Local\Programs\Python\Python39\lib\site-packages\telegram\bot.py", line 130, in decorator
    result = func(*args, **kwargs)
  File "C:\Users\user\AppData\Local\Programs\Python\Python39\lib\site-packages\telegram\bot.py", line 2861, in get_updates
    self._post(
  File "C:\Users\user\AppData\Local\Programs\Python\Python39\lib\site-packages\telegram\bot.py", line 295, in _post
    return self.request.post(
  File "C:\Users\user\AppData\Local\Programs\Python\Python39\lib\site-packages\telegram\utils\request.py", line 356, in post
    result = self._request_wrapper(
  File "C:\Users\user\AppData\Local\Programs\Python\Python39\lib\site-packages\telegram\utils\request.py", line 283, in _request_wrapper
    raise Conflict(message)
telegram.error.Conflict: Conflict: terminated by other getUpdates request; make sure that only one bot instance is running
2021-09-15 10:00:11,411 - telegram.ext.updater - ERROR - Error while getting Updates: Conflict: terminated by other getUpdates request; make sure that only one bot instance is running
2021-09-15 10:00:11,411 - telegram.ext.dispatcher - ERROR - No error handlers are registered, logging exception.
Traceback (most recent call last):
  File "C:\Users\user\AppData\Local\Programs\Python\Python39\lib\site-packages\telegram\ext\updater.py", line 646, in _network_loop_retry
    if not action_cb():
  File "C:\Users\user\AppData\Local\Programs\Python\Python39\lib\site-packages\telegram\ext\updater.py", line 597, in polling_action_cb
    updates = self.bot.get_updates(
  File "C:\Users\user\AppData\Local\Programs\Python\Python39\lib\site-packages\telegram\ext\extbot.py", line 222, in get_updates
    updates = super().get_updates(
  File "C:\Users\user\AppData\Local\Programs\Python\Python39\lib\site-packages\telegram\bot.py", line 130, in decorator
    result = func(*args, **kwargs)
  File "C:\Users\user\AppData\Local\Programs\Python\Python39\lib\site-packages\telegram\bot.py", line 2861, in get_updates
    self._post(
  File "C:\Users\user\AppData\Local\Programs\Python\Python39\lib\site-packages\telegram\bot.py", line 295, in _post
    return self.request.post(
  File "C:\Users\user\AppData\Local\Programs\Python\Python39\lib\site-packages\telegram\utils\request.py", line 356, in post
    result = self._request_wrapper(
  File "C:\Users\user\AppData\Local\Programs\Python\Python39\lib\site-packages\telegram\utils\request.py", line 283, in _request_wrapper
    raise Conflict(message)
telegram.error.Conflict: Conflict: terminated by other getUpdates request; make sure that only one bot instance is running
2021-09-15 10:00:14,888 - telegram.ext.updater - ERROR - Error while getting Updates: Conflict: terminated by other getUpdates request; make sure that only one bot instance is running
2021-09-15 10:00:14,893 - telegram.ext.dispatcher - ERROR - No error handlers are registered, logging exception.
Traceback (most recent call last):
  File "C:\Users\user\AppData\Local\Programs\Python\Python39\lib\site-packages\telegram\ext\updater.py", line 646, in _network_loop_retry
    if not action_cb():
  File "C:\Users\user\AppData\Local\Programs\Python\Python39\lib\site-packages\telegram\ext\updater.py", line 597, in polling_action_cb
    updates = self.bot.get_updates(
  File "C:\Users\user\AppData\Local\Programs\Python\Python39\lib\site-packages\telegram\ext\extbot.py", line 222, in get_updates
    updates = super().get_updates(
  File "C:\Users\user\AppData\Local\Programs\Python\Python39\lib\site-packages\telegram\bot.py", line 130, in decorator
    result = func(*args, **kwargs)
  File "C:\Users\user\AppData\Local\Programs\Python\Python39\lib\site-packages\telegram\bot.py", line 2861, in get_updates
    self._post(
  File "C:\Users\user\AppData\Local\Programs\Python\Python39\lib\site-packages\telegram\bot.py", line 295, in _post
    return self.request.post(
  File "C:\Users\user\AppData\Local\Programs\Python\Python39\lib\site-packages\telegram\utils\request.py", line 356, in post
    result = self._request_wrapper(
  File "C:\Users\user\AppData\Local\Programs\Python\Python39\lib\site-packages\telegram\utils\request.py", line 283, in _request_wrapper
    raise Conflict(message)
telegram.error.Conflict: Conflict: terminated by other getUpdates request; make sure that only one bot instance is running
2021-09-15 10:00:22,587 - telegram.ext.updater - ERROR - Error while getting Updates: Conflict: terminated by other getUpdates request; make sure that only one bot instance is running
2021-09-15 10:00:22,587 - telegram.ext.dispatcher - ERROR - No error handlers are registered, logging exception.
Traceback (most recent call last):
  File "C:\Users\user\AppData\Local\Programs\Python\Python39\lib\site-packages\telegram\ext\updater.py", line 646, in _network_loop_retry
    if not action_cb():
  File "C:\Users\user\AppData\Local\Programs\Python\Python39\lib\site-packages\telegram\ext\updater.py", line 597, in polling_action_cb
    updates = self.bot.get_updates(
  File "C:\Users\user\AppData\Local\Programs\Python\Python39\lib\site-packages\telegram\ext\extbot.py", line 222, in get_updates
    updates = super().get_updates(
  File "C:\Users\user\AppData\Local\Programs\Python\Python39\lib\site-packages\telegram\bot.py", line 130, in decorator
    result = func(*args, **kwargs)
  File "C:\Users\user\AppData\Local\Programs\Python\Python39\lib\site-packages\telegram\bot.py", line 2861, in get_updates
    self._post(
  File "C:\Users\user\AppData\Local\Programs\Python\Python39\lib\site-packages\telegram\bot.py", line 295, in _post
    return self.request.post(
  File "C:\Users\user\AppData\Local\Programs\Python\Python39\lib\site-packages\telegram\utils\request.py", line 356, in post
    result = self._request_wrapper(
  File "C:\Users\user\AppData\Local\Programs\Python\Python39\lib\site-packages\telegram\utils\request.py", line 283, in _request_wrapper
    raise Conflict(message)
telegram.error.Conflict: Conflict: terminated by other getUpdates request; make sure that only one bot instance is running
2021-09-15 10:00:27,768 - telegram.ext.updater - ERROR - Error while getting Updates: Conflict: terminated by other getUpdates request; make sure that only one bot instance is running
2021-09-15 10:00:27,768 - telegram.ext.dispatcher - ERROR - No error handlers are registered, logging exception.
Traceback (most recent call last):
  File "C:\Users\user\AppData\Local\Programs\Python\Python39\lib\site-packages\telegram\ext\updater.py", line 646, in _network_loop_retry
    if not action_cb():
  File "C:\Users\user\AppData\Local\Programs\Python\Python39\lib\site-packages\telegram\ext\updater.py", line 597, in polling_action_cb
    updates = self.bot.get_updates(
  File "C:\Users\user\AppData\Local\Programs\Python\Python39\lib\site-packages\telegram\ext\extbot.py", line 222, in get_updates
    updates = super().get_updates(
  File "C:\Users\user\AppData\Local\Programs\Python\Python39\lib\site-packages\telegram\bot.py", line 130, in decorator
    result = func(*args, **kwargs)
  File "C:\Users\user\AppData\Local\Programs\Python\Python39\lib\site-packages\telegram\bot.py", line 2861, in get_updates
    self._post(
  File "C:\Users\user\AppData\Local\Programs\Python\Python39\lib\site-packages\telegram\bot.py", line 295, in _post
    return self.request.post(
  File "C:\Users\user\AppData\Local\Programs\Python\Python39\lib\site-packages\telegram\utils\request.py", line 356, in post
    result = self._request_wrapper(
  File "C:\Users\user\AppData\Local\Programs\Python\Python39\lib\site-packages\telegram\utils\request.py", line 283, in _request_wrapper
    raise Conflict(message)
telegram.error.Conflict: Conflict: terminated by other getUpdates request; make sure that only one bot instance is running
2021-09-15 10:00:39,261 - telegram.ext.updater - ERROR - Error while getting Updates: Conflict: terminated by other getUpdates request; make sure that only one bot instance is running
2021-09-15 10:00:39,261 - telegram.ext.dispatcher - ERROR - No error handlers are registered, logging exception.
Traceback (most recent call last):
  File "C:\Users\user\AppData\Local\Programs\Python\Python39\lib\site-packages\telegram\ext\updater.py", line 646, in _network_loop_retry
    if not action_cb():
  File "C:\Users\user\AppData\Local\Programs\Python\Python39\lib\site-packages\telegram\ext\updater.py", line 597, in polling_action_cb
    updates = self.bot.get_updates(
  File "C:\Users\user\AppData\Local\Programs\Python\Python39\lib\site-packages\telegram\ext\extbot.py", line 222, in get_updates
    updates = super().get_updates(
  File "C:\Users\user\AppData\Local\Programs\Python\Python39\lib\site-packages\telegram\bot.py", line 130, in decorator
    result = func(*args, **kwargs)
  File "C:\Users\user\AppData\Local\Programs\Python\Python39\lib\site-packages\telegram\bot.py", line 2861, in get_updates
    self._post(
  File "C:\Users\user\AppData\Local\Programs\Python\Python39\lib\site-packages\telegram\bot.py", line 295, in _post
    return self.request.post(
  File "C:\Users\user\AppData\Local\Programs\Python\Python39\lib\site-packages\telegram\utils\request.py", line 356, in post
    result = self._request_wrapper(
  File "C:\Users\user\AppData\Local\Programs\Python\Python39\lib\site-packages\telegram\utils\request.py", line 283, in _request_wrapper
    raise Conflict(message)
telegram.error.Conflict: Conflict: terminated by other getUpdates request; make sure that only one bot instance is running
2021-09-15 10:00:43,375 - telegram.ext.updater - ERROR - Error while getting Updates: Conflict: terminated by other getUpdates request; make sure that only one bot instance is running
2021-09-15 10:00:43,375 - telegram.ext.dispatcher - ERROR - No error handlers are registered, logging exception.
Traceback (most recent call last):
  File "C:\Users\user\AppData\Local\Programs\Python\Python39\lib\site-packages\telegram\ext\updater.py", line 646, in _network_loop_retry
    if not action_cb():
  File "C:\Users\user\AppData\Local\Programs\Python\Python39\lib\site-packages\telegram\ext\updater.py", line 597, in polling_action_cb
    updates = self.bot.get_updates(
  File "C:\Users\user\AppData\Local\Programs\Python\Python39\lib\site-packages\telegram\ext\extbot.py", line 222, in get_updates
    updates = super().get_updates(
  File "C:\Users\user\AppData\Local\Programs\Python\Python39\lib\site-packages\telegram\bot.py", line 130, in decorator
    result = func(*args, **kwargs)
  File "C:\Users\user\AppData\Local\Programs\Python\Python39\lib\site-packages\telegram\bot.py", line 2861, in get_updates
    self._post(
  File "C:\Users\user\AppData\Local\Programs\Python\Python39\lib\site-packages\telegram\bot.py", line 295, in _post
    return self.request.post(
  File "C:\Users\user\AppData\Local\Programs\Python\Python39\lib\site-packages\telegram\utils\request.py", line 356, in post
    result = self._request_wrapper(
  File "C:\Users\user\AppData\Local\Programs\Python\Python39\lib\site-packages\telegram\utils\request.py", line 283, in _request_wrapper
    raise Conflict(message)
telegram.error.Conflict: Conflict: terminated by other getUpdates request; make sure that only one bot instance is running
2021-09-15 10:00:53,083 - root - INFO - Bot started...
2021-09-15 10:00:53,083 - apscheduler.scheduler - INFO - Scheduler started
2021-09-15 10:01:03,102 - root - INFO - œÓÎ¸ÁÓ‚‡ÚÂÎ¸ ≈Í‡ÚÂËÌ‡ Ì‡Ê‡Î /start
2021-09-15 10:04:19,186 - root - INFO - Bot started...
2021-09-15 10:04:19,191 - apscheduler.scheduler - INFO - Scheduler started
2021-09-15 10:04:24,755 - root - INFO - œÓÎ¸ÁÓ‚‡ÚÂÎ¸ danilova_kate Ì‡Ê‡Î /start
2021-09-17 17:13:16,742 - root - INFO - Bot started...
2021-09-17 17:13:16,844 - apscheduler.scheduler - INFO - Scheduler started
2021-09-17 17:13:33,645 - root - INFO - /planet
2021-09-17 17:14:47,953 - root - INFO - Bot started...
2021-09-17 17:15:12,699 - root - INFO - Bot started...
2021-09-17 17:15:12,703 - apscheduler.scheduler - INFO - Scheduler started
2021-09-17 17:15:22,740 - root - INFO - Venus
2021-09-17 17:18:34,656 - root - INFO - Bot started...
2021-09-17 17:18:34,672 - apscheduler.scheduler - INFO - Scheduler started
2021-09-17 17:18:41,979 - root - INFO - Venus
2021-09-17 17:20:13,433 - root - INFO - Bot started...
2021-09-17 17:20:13,438 - apscheduler.scheduler - INFO - Scheduler started
2021-09-17 17:20:19,276 - root - INFO - Venus
2021-09-17 17:21:43,647 - root - INFO - Bot started...
2021-09-17 17:21:43,651 - apscheduler.scheduler - INFO - Scheduler started
2021-09-17 17:21:46,148 - telegram.ext.dispatcher - ERROR - No error handlers are registered, logging exception.
Traceback (most recent call last):
  File "C:\Users\user\AppData\Local\Programs\Python\Python39\lib\site-packages\telegram\ext\dispatcher.py", line 555, in process_update
    handler.handle_update(update, self, check, context)
  File "C:\Users\user\AppData\Local\Programs\Python\Python39\lib\site-packages\telegram\ext\handler.py", line 198, in handle_update
    return self.callback(update, context)
  File "d:\Python\learn1\simplebot\bot.py", line 37, in planet_bot
    planet = ephem.myplanet(datetime.date.today())
AttributeError: module 'ephem' has no attribute 'myplanet'
2021-09-17 17:22:49,844 - root - INFO - Bot started...
2021-09-17 17:22:49,844 - apscheduler.scheduler - INFO - Scheduler started
2021-09-17 17:22:54,068 - telegram.ext.dispatcher - ERROR - No error handlers are registered, logging exception.
Traceback (most recent call last):
  File "C:\Users\user\AppData\Local\Programs\Python\Python39\lib\site-packages\telegram\ext\dispatcher.py", line 555, in process_update
    handler.handle_update(update, self, check, context)
  File "C:\Users\user\AppData\Local\Programs\Python\Python39\lib\site-packages\telegram\ext\handler.py", line 198, in handle_update
    return self.callback(update, context)
  File "d:\Python\learn1\simplebot\bot.py", line 37, in planet_bot
    planet = ephem.myplanet(datetime.date.today())
AttributeError: module 'ephem' has no attribute 'myplanet'
2021-09-17 17:23:38,922 - root - INFO - Bot started...
2021-09-17 17:23:38,922 - apscheduler.scheduler - INFO - Scheduler started
2021-09-17 17:23:43,884 - telegram.ext.dispatcher - ERROR - No error handlers are registered, logging exception.
Traceback (most recent call last):
  File "C:\Users\user\AppData\Local\Programs\Python\Python39\lib\site-packages\telegram\ext\dispatcher.py", line 555, in process_update
    handler.handle_update(update, self, check, context)
  File "C:\Users\user\AppData\Local\Programs\Python\Python39\lib\site-packages\telegram\ext\handler.py", line 198, in handle_update
    return self.callback(update, context)
  File "d:\Python\learn1\simplebot\bot.py", line 37, in planet_bot
    planet = ephem.myplanet(datetime.date.today())
AttributeError: module 'ephem' has no attribute 'myplanet'
2021-09-17 17:23:49,805 - root - INFO - œÓÎ¸ÁÓ‚‡ÚÂÎ¸ danilova_kate Ì‡Ê‡Î /start
2021-09-17 17:23:55,928 - telegram.ext.dispatcher - ERROR - No error handlers are registered, logging exception.
Traceback (most recent call last):
  File "C:\Users\user\AppData\Local\Programs\Python\Python39\lib\site-packages\telegram\ext\dispatcher.py", line 555, in process_update
    handler.handle_update(update, self, check, context)
  File "C:\Users\user\AppData\Local\Programs\Python\Python39\lib\site-packages\telegram\ext\handler.py", line 198, in handle_update
    return self.callback(update, context)
  File "d:\Python\learn1\simplebot\bot.py", line 37, in planet_bot
    planet = ephem.myplanet(datetime.date.today())
AttributeError: module 'ephem' has no attribute 'myplanet'
2021-09-17 17:24:31,958 - root - INFO - Bot started...
2021-09-17 17:24:31,959 - apscheduler.scheduler - INFO - Scheduler started
2021-09-17 17:25:10,081 - root - INFO - Bot started...
2021-09-17 17:25:10,085 - apscheduler.scheduler - INFO - Scheduler started
2021-09-17 17:25:17,476 - telegram.ext.dispatcher - ERROR - No error handlers are registered, logging exception.
Traceback (most recent call last):
  File "C:\Users\user\AppData\Local\Programs\Python\Python39\lib\site-packages\telegram\ext\dispatcher.py", line 555, in process_update
    handler.handle_update(update, self, check, context)
  File "C:\Users\user\AppData\Local\Programs\Python\Python39\lib\site-packages\telegram\ext\handler.py", line 198, in handle_update
    return self.callback(update, context)
  File "d:\Python\learn1\simplebot\bot.py", line 37, in planet_bot
    planet = ephem.myplanet(datetime.date.today())
AttributeError: module 'ephem' has no attribute 'myplanet'
2021-09-20 15:25:41,831 - root - INFO - Bot started...
2021-09-20 15:25:41,831 - apscheduler.scheduler - INFO - Scheduler started
2021-09-20 15:26:41,112 - root - INFO - Bot started...
2021-09-20 15:26:41,112 - apscheduler.scheduler - INFO - Scheduler started
2021-09-20 15:29:24,753 - root - INFO - Bot started...
2021-09-20 15:29:24,753 - apscheduler.scheduler - INFO - Scheduler started
2021-09-20 15:29:41,165 - root - INFO - Bot started...
2021-09-20 15:29:41,166 - apscheduler.scheduler - INFO - Scheduler started
2021-09-20 15:33:46,126 - root - INFO - Bot started...
2021-09-20 15:33:46,127 - apscheduler.scheduler - INFO - Scheduler started
2021-09-20 15:35:54,967 - root - INFO - Bot started...
2021-09-20 15:35:54,969 - apscheduler.scheduler - INFO - Scheduler started
2021-09-20 15:36:06,345 - root - INFO - ghbdtm
2021-09-20 15:37:56,380 - root - INFO - œÓÎ¸ÁÓ‚‡ÚÂÎ¸ danilova_kate Ì‡Ê‡Î /start
2021-09-20 15:38:33,393 - root - INFO - Bot started...
2021-09-20 15:38:33,394 - apscheduler.scheduler - INFO - Scheduler started
2021-09-20 15:38:44,606 - root - INFO - œÓÎ¸ÁÓ‚‡ÚÂÎ¸ danilova_kate Ì‡Ê‡Î /start
2021-09-20 15:38:54,848 - root - INFO - Mars
2021-09-20 15:39:16,173 - root - INFO - ÔË‚ÂÚ
